Workbook

Sheet Instructions
A1: GrAid — Identification Scoring Evaluation Workbook (Exact Matching)
A3: Purpose | B3: Computes transcription accuracy and identification scoring accuracy for the exact-matching scorer, with the confusion table, false accept/reject rates, confidence intervals, and error attribution.
A5: Colour legend | B5: Blue text = you type or paste it (inputs). Black text = formula, do not overwrite. Yellow header = input column. Blue header = calculated column.
A7: Steps
A8: 1 | B8: Open the Settings sheet and check the confidence level (z) and the accuracy target.
A9: 2 | B9: On the Data sheet, delete the 10 EXAMPLE rows (rows 5–14, columns A–L only; keep the formulas in columns M–Y) and enter one row per identification answer, starting at row 5. The sheet supports up to 200 answers (rows 5–204).
A10: 3 | B10: Column C is the answer key; column D lists accepted variants separated by | with no spaces around it (for example: magellan|f magellan). Decide the variants BEFORE data collection and do not change them afterwards.
A11: 4 | B11: Column E is the reference transcription typed by the research team. Column F is GrAid’s raw transcription. Column G is GrAid’s text after the LLM correction step (copy column F if there is no correction step). The scoring test uses column G.
A12: 5 | B12: Column H is the professor's judgment of the written answer (1 = correct, 0 = incorrect), made without seeing GrAid's score. Column I = 1 ONLY if GrAid routed the answer to mandatory human review (its status is needs_review), otherwise 0. Do NOT set column I from the presence of a flag: GrAid attaches an automatic 'identification_no_match' flag to every wrong answer, so counting those would make Analysis E read close to 100% and measure nothing. Report the two numbers separately in Chapter 4 if both are useful — answers routed to mandatory review, and answers carrying a flag of any kind.
A13: 6 | B13: Columns J and K are the character errors and word errors for GrAid’s raw transcription against the reference transcription (edit distance counts). Take them from GrAid’s per-answer CER/WER export, or from your own script. Excel has no built-in edit-distance function.
A14: 7 | B14: After reading the Summary, fill in column L for every disagreement (rows where column Y is FA or FR) by choosing a category from the drop-down list.
A16: Normalization rule used before comparing | B16: Text is converted to lowercase, extra and leading/trailing spaces are removed, and these characters are deleted: . , ; : ! ? " ' ’ “ ”. Hyphens are kept. Articles ("the"), plurals, and word order are NOT normalized. If your Chapter 3 rule differs, edit the formulas in columns M–Q of the Data sheet.
A18: Definitions
A19: Rule check (Analysis B) | B19: Exact-matching rule applied to the REFERENCE transcription, compared with the professor’s judgment. Shows the limit of exact matching itself (spelling variants, synonyms, incomplete variants list).
A20: End-to-end (Analysis C) | B20: Exact-matching rule applied to GrAid’s (corrected) transcription, compared with the professor’s judgment. This is the real scoring accuracy.
A21: TA / FA / FR / TR | B21: TA = true accept (GrAid gave credit, professor correct). FA = false accept (GrAid gave credit, professor incorrect). FR = false reject (GrAid gave zero, professor correct). TR = true reject.
A22: Pooled CER / WER | B22: Total errors divided by total reference characters / words across all answers (one wrong word in one answer does not make the whole study 100%).
A23: Exact-transcription rate | B23: Share of answers whose transcription equals the reference after normalization (zero word errors).
A24: Wilson interval | B24: 95% confidence interval for a proportion, computed with the z value on the Settings sheet.
A26: Note | B26: The 10 rows on the Data sheet are ILLUSTRATIVE EXAMPLES made up to show the expected format. They are not study data. Delete them before using the workbook.

Sheet Summary
A1: Summary of results
A2: Values are calculated from the Data sheet. While the example rows are present, these are NOT study results.
A4: Analysis A — Transcription (identification answers)
A5: Number of answers | B5: =COUNTA(Data!$A$5:$A$254)
A6: Total reference characters | B6: =SUM(Data!$R$5:$R$254)
A7: Total character errors | B7: =SUM(Data!$J$5:$J$254)
A8: Pooled CER | B8: =IF(B6=0,"",B7/B6) | C8: Character errors ÷ reference characters
A9: Total reference words | B9: =SUM(Data!$S$5:$S$254)
A10: Total word errors | B10: =SUM(Data!$K$5:$K$254)
A11: Pooled WER | B11: =IF(B9=0,"",B10/B9) | C11: Word errors ÷ reference words
A12: Word-level accuracy (1 − WER) | B12: =IF(B11="","",1-B11)
A13: Word-level accuracy target met? | B13: =IF(B12="","",IF(B12>=Settings!B4,"Met","Not met")) | C13: Compares with the target on the Settings sheet
A14: Exact-transcription rate, raw | B14: =IF(B5=0,"",SUM(Data!$V$5:$V$254)/B5) | C14: Share of answers with no difference from the reference after normalization
A15: Exact-transcription rate, after correction step | B15: =IF(B5=0,"",SUM(Data!$W$5:$W$254)/B5)
A16: Change from the correction step (percentage points) | B16: =IF(OR(B14="",B15=""),"",(B15-B14)*100) | C16: Positive = correction helped; negative = correction hurt
A18: Analysis B — Rule check (exact rule on the reference transcription vs professor)
B19: Professor: correct | C19: Professor: incorrect | D19: Total
A20: GrAid: full credit | B20: =COUNTIF(Data!$X$5:$X$254,"TA") | C20: =COUNTIF(Data!$X$5:$X$254,"FA") | D20: =B20+C20 | E20: B = true accepts (TA); C = false accepts (FA)
A21: GrAid: zero credit | B21: =COUNTIF(Data!$X$5:$X$254,"FR") | C21: =COUNTIF(Data!$X$5:$X$254,"TR") | D21: =B21+C21 | E21: B = false rejects (FR); C = true rejects (TR)
A22: Total | B22: =B20+B21 | C22: =C20+C21 | D22: =D20+D21
A23: Number of answers scored | B23: =D22 | C23: Limit of exact matching itself
A24: Accuracy = (TA + TR) ÷ all | B24: =IF(B23=0,"",(B20+C21)/B23)
A25: False accept rate = FA ÷ (FA + TR) | B25: =IF(C22=0,"",C20/C22) | C25: Wrongly credited ÷ professor-incorrect answers
A26: False reject rate = FR ÷ (FR + TA) | B26: =IF(B22=0,"",B21/B22) | C26: Wrongly rejected ÷ professor-correct answers
A27: 95% CI for accuracy, lower (Wilson) | B27: =IF(B23=0,"",(B24+Settings!$B$2^2/(2*B23)-Settings!$B$2*SQRT(B24*(1-B24)/B23+Settings!$B$2^2/(4*B23^2)))/(1+Settings!$B$2^2/B23))
A28: 95% CI for accuracy, upper (Wilson) | B28: =IF(B23=0,"",(B24+Settings!$B$2^2/(2*B23)+Settings!$B$2*SQRT(B24*(1-B24)/B23+Settings!$B$2^2/(4*B23^2)))/(1+Settings!$B$2^2/B23))
A29: Accuracy target met? (point estimate) | B29: =IF(B24="","",IF(B24>=Settings!B3,"Met","Not met")) | C29: Also check whether the CI lower bound is below the target
A31: Analysis C — End-to-end (exact rule on GrAid’s corrected transcription vs professor)
B32: Professor: correct | C32: Professor: incorrect | D32: Total
A33: GrAid: full credit | B33: =COUNTIF(Data!$Y$5:$Y$254,"TA") | C33: =COUNTIF(Data!$Y$5:$Y$254,"FA") | D33: =B33+C33 | E33: B = true accepts (TA); C = false accepts (FA)
A34: GrAid: zero credit | B34: =COUNTIF(Data!$Y$5:$Y$254,"FR") | C34: =COUNTIF(Data!$Y$5:$Y$254,"TR") | D34: =B34+C34 | E34: B = false rejects (FR); C = true rejects (TR)
A35: Total | B35: =B33+B34 | C35: =C33+C34 | D35: =D33+D34
A36: Number of answers scored | B36: =D35 | C36: Actual scoring accuracy
A37: Accuracy = (TA + TR) ÷ all | B37: =IF(B36=0,"",(B33+C34)/B36)
A38: False accept rate = FA ÷ (FA + TR) | B38: =IF(C35=0,"",C33/C35) | C38: Wrongly credited ÷ professor-incorrect answers
A39: False reject rate = FR ÷ (FR + TA) | B39: =IF(B35=0,"",B34/B35) | C39: Wrongly rejected ÷ professor-correct answers
A40: 95% CI for accuracy, lower (Wilson) | B40: =IF(B36=0,"",(B37+Settings!$B$2^2/(2*B36)-Settings!$B$2*SQRT(B37*(1-B37)/B36+Settings!$B$2^2/(4*B36^2)))/(1+Settings!$B$2^2/B36))
A41: 95% CI for accuracy, upper (Wilson) | B41: =IF(B36=0,"",(B37+Settings!$B$2^2/(2*B36)+Settings!$B$2*SQRT(B37*(1-B37)/B36+Settings!$B$2^2/(4*B36^2)))/(1+Settings!$B$2^2/B36))
A42: Accuracy target met? (point estimate) | B42: =IF(B37="","",IF(B37>=Settings!B3,"Met","Not met")) | C42: Also check whether the CI lower bound is below the target
A44: Cost of transcription errors (B − C, percentage points) | B44: =IF(OR(B24="",B37=""),"",(B24-B37)*100) | C44: Accuracy lost because GrAid’s text differs from the reference
...

Sheet Settings
A1: Settings
A2: z value for confidence interval | B2: 1.96 | C2: 1.96 = 95% confidence (standard normal value)
A3: Accuracy target (identification) | B3: 0.95 | C3: From Chapter 3 (at least 95%). Change if the target is revised.
A4: Word-level accuracy target (1 − WER) | B4: 0.8 | C4: From Chapter 3 (at least 80%).
A6: Disagreement categories (used by the drop-down in Data column L)
A7: Transcription error
A8: Correction-step error
A9: Spelling variant or synonym not on list
A10: Professor inconsistency
A11: Key error
A12: Other

Sheet Data
A1: Identification answers — one row per answer
A2: Rows 5–14 are ILLUSTRATIVE EXAMPLES (not study data). Delete columns A–L of those rows and enter your data; keep formulas in M–Y. Up to 200 answers (rows 5–204).
A4: Item ID | B4: Professor | C4: Answer key | D4: Accepted variants (separate with |) | E4: Reference transcription (team) | F4: GrAid raw transcription | G4: GrAid corrected transcription (used for scoring) | H4: Professor judgment (1 = correct, 0 = incorrect) | I4: Routed to review by GrAid — status = needs_review (1/0) | J4: Char errors (raw vs reference) | K4: Word errors (raw vs reference) | L4: Disagreement category | M4: Norm. key | N4: Norm. variants | O4: Norm. reference | P4: Norm. raw | Q4: Norm. corrected | R4: Reference chars | S4: Reference words | T4: Rule check: match (1/0) | U4: End-to-end: match (1/0) | V4: Exact transcription, raw (1/0) | W4: Exact transcription, corrected (1/0) | X4: Rule check class | Y4: End-to-end class
A5: E01 | B5: P1 | C5: mitosis | E5: mitosis | F5: mitosis | G5: mitosis | H5: 1 | I5: 0 | J5: 0 | K5: 0 | M5: =IF($A5="","",LOWER(TRIM(SUBSTITUTE(SUBSTITUTE(SUBSTITUTE(SUBSTITUTE(SUBSTITUTE(SUBSTITUTE(SUBSTITUTE(SUBSTITUTE(SUBSTITUTE(SUBSTITUTE(SUBSTITUTE(C5,".",""),",",""),";",""),":",""),"!",""),"?",""),"""",""),"'",""),"’",""),"“",""),"”","")))) | N5: =IF($A5="","",SUBSTITUTE(SUBSTITUTE(LOWER(TRIM(SUBSTITUTE(SUBSTITUTE(SUBSTITUTE(SUBSTITUTE(SUBSTITUTE(SUBSTITUTE(SUBSTITUTE(SUBSTITUTE(SUBSTITUTE(SUBSTITUTE(SUBSTITUTE(D5,".",""),",",""),";",""),":",""),"!",""),"?",""),"""",""),"'",""),"’",""),"“",""),"”","")))," |","|"),"| ","|")) | O5: =IF($A5="","",LOWER(TRIM(SUBSTITUTE(SUBSTITUTE(SUBSTITUTE(SUBSTITUTE(SUBSTITUTE(SUBSTITUTE(SUBSTITUTE(SUBSTITUTE(SUBSTITUTE(SUBSTITUTE(SUBSTITUTE(E5,".",""),",",""),";",""),":",""),"!",""),"?",""),"""",""),"'",""),"’",""),"“",""),"”","")))) | P5: =IF($A5="","",LOWER(TRIM(SUBSTITUTE(SUBSTITUTE(SUBSTITUTE(SUBSTITUTE(SUBSTITUTE(SUBSTITUTE(SUBSTITUTE(SUBSTITUTE(SUBSTITUTE(SUBSTITUTE(SUBSTITUTE(F5,".",""),",",""),";",""),":",""),"!",""),"?",""),"""",""),"'",""),"’",""),"“",""),"”","")))) | Q5: =IF($A5="","",LOWER(TRIM(SUBSTITUTE(SUBSTITUTE(SUBSTITUTE(SUBSTITUTE(SUBSTITUTE(SUBSTITUTE(SUBSTITUTE(SUBSTITUTE(SUBSTITUTE(SUBSTITUTE(SUBSTITUTE(G5,".",""),",",""),";",""),":",""),"!",""),"?",""),"""",""),"'",""),"’",""),"“",""),"”","")))) | R5: =IF($A5="","",LEN(O5)) | S5: =IF($A5="","",IF(O5="",0,LEN(O5)-LEN(SUBSTITUTE(O5," ",""))+1)) | T5: =IF($A5="","",IF(AND(O5<>"",OR(O5=M5,AND(N5<>"",ISNUMBER(FIND("|"&O5&"|","|"&N5&"|"))))),1,0)) | U5: =IF($A5="","",IF(AND(Q5<>"",OR(Q5=M5,AND(N5<>"",ISNUMBER(FIND("|"&Q5&"|","|"&N5&"|"))))),1,0)) | V5: =IF($A5="","",IF(P5=O5,1,0)) | W5: =IF($A5="","",IF(Q5=O5,1,0)) | X5: =IF(OR($A5="",$H5=""),"",IF(AND($H5=1,T5=1),"TA",IF(AND($H5=0,T5=1),"FA",IF($H5=1,"FR","TR")))) | Y5: =IF(OR($A5="",$H5=""),"",IF(AND($H5=1,U5=1),"TA",IF(AND($H5=0,U5=1),"FA",IF($H5=1,"FR","TR"))))
A6: E02 | B6: P1 | C6: photosynthesis | E6: photosynthesis | F6: photosinthesis | G6: photosynthesis | H6: 1 | I6: 0 | J6: 1 | K6: 1 | M6: =IF($A6="","",LOWER(TRIM(SUBSTITUTE(SUBSTITUTE(SUBSTITUTE(SUBSTITUTE(SUBSTITUTE(SUBSTITUTE(SUBSTITUTE(SUBSTITUTE(SUBSTITUTE(SUBSTITUTE(SUBSTITUTE(C6,".",""),",",""),";",""),":",""),"!",""),"?",""),"""",""),"'",""),"’",""),"“",""),"”","")))) | N6: =IF($A6="","",SUBSTITUTE(SUBSTITUTE(LOWER(TRIM(SUBSTITUTE(SUBSTITUTE(SUBSTITUTE(SUBSTITUTE(SUBSTITUTE(SUBSTITUTE(SUBSTITUTE(SUBSTITUTE(SUBSTITUTE(SUBSTITUTE(SUBSTITUTE(D6,".",""),",",""),";",""),":",""),"!",""),"?",""),"""",""),"'",""),"’",""),"“",""),"”","")))," |","|"),"| ","|")) | O6: =IF($A6="","",LOWER(TRIM(SUBSTITUTE(SUBSTITUTE(SUBSTITUTE(SUBSTITUTE(SUBSTITUTE(SUBSTITUTE(SUBSTITUTE(SUBSTITUTE(SUBSTITUTE(SUBSTITUTE(SUBSTITUTE(E6,".",""),",",""),";",""),":",""),"!",""),"?",""),"""",""),"'",""),"’",""),"“",""),"”","")))) | P6: =IF($A6="","",LOWER(TRIM(SUBSTITUTE(SUBSTITUTE(SUBSTITUTE(SUBSTITUTE(SUBSTITUTE(SUBSTITUTE(SUBSTITUTE(SUBSTITUTE(SUBSTITUTE(SUBSTITUTE(SUBSTITUTE(F6,".",""),",",""),";",""),":",""),"!",""),"?",""),"""",""),"'",""),"’",""),"“",""),"”","")))) | Q6: =IF($A6="","",LOWER(TRIM(SUBSTITUTE(SUBSTITUTE(SUBSTITUTE(SUBSTITUTE(SUBSTITUTE(SUBSTITUTE(SUBSTITUTE(SUBSTITUTE(SUBSTITUTE(SUBSTITUTE(SUBSTITUTE(G6,".",""),",",""),";",""),":",""),"!",""),"?",""),"""",""),"'",""),"’",""),"“",""),"”","")))) | R6: =IF($A6="","",LEN(O6)) | S6: =IF($A6="","",IF(O6="",0,LEN(O6)-LEN(SUBSTITUTE(O6," ",""))+1)) | T6: =IF($A6="","",IF(AND(O6<>"",OR(O6=M6,AND(N6<>"",ISNUMBER(FIND("|"&O6&"|","|"&N6&"|"))))),1,0)) | U6: =IF($A6="","",IF(AND(Q6<>"",OR(Q6=M6,AND(N6<>"",ISNUMBER(FIND("|"&Q6&"|","|"&N6&"|"))))),1,0)) | V6: =IF($A6="","",IF(P6=O6,1,0)) | W6: =IF($A6="","",IF(Q6=O6,1,0)) | X6: =IF(OR($A6="",$H6=""),"",IF(AND($H6=1,T6=1),"TA",IF(AND($H6=0,T6=1),"FA",IF($H6=1,"FR","TR")))) | Y6: =IF(OR($A6="",$H6=""),"",IF(AND($H6=1,U6=1),"TA",IF(AND($H6=0,U6=1),"FA",IF($H6=1,"FR","TR"))))
A7: E03 | B7: P1 | C7: democracy | E7: democracy | F7: democrasy | G7: democrasy | H7: 1 | I7: 0 | J7: 1 | K7: 1 | L7: Transcription error | M7: =IF($A7="","",LOWER(TRIM(SUBSTITUTE(SUBSTITUTE(SUBSTITUTE(SUBSTITUTE(SUBSTITUTE(SUBSTITUTE(SUBSTITUTE(SUBSTITUTE(SUBSTITUTE(SUBSTITUTE(SUBSTITUTE(C7,".",""),",",""),";",""),":",""),"!",""),"?",""),"""",""),"'",""),"’",""),"“",""),"”","")))) | N7: =IF($A7="","",SUBSTITUTE(SUBSTITUTE(LOWER(TRIM(SUBSTITUTE(SUBSTITUTE(SUBSTITUTE(SUBSTITUTE(SUBSTITUTE(SUBSTITUTE(SUBSTITUTE(SUBSTITUTE(SUBSTITUTE(SUBSTITUTE(SUBSTITUTE(D7,".",""),",",""),";",""),":",""),"!",""),"?",""),"""",""),"'",""),"’",""),"“",""),"”","")))," |","|"),"| ","|")) | O7: =IF($A7="","",LOWER(TRIM(SUBSTITUTE(SUBSTITUTE(SUBSTITUTE(SUBSTITUTE(SUBSTITUTE(SUBSTITUTE(SUBSTITUTE(SUBSTITUTE(SUBSTITUTE(SUBSTITUTE(SUBSTITUTE(E7,".",""),",",""),";",""),":",""),"!",""),"?",""),"""",""),"'",""),"’",""),"“",""),"”","")))) | P7: =IF($A7="","",LOWER(TRIM(SUBSTITUTE(SUBSTITUTE(SUBSTITUTE(SUBSTITUTE(SUBSTITUTE(SUBSTITUTE(SUBSTITUTE(SUBSTITUTE(SUBSTITUTE(SUBSTITUTE(SUBSTITUTE(F7,".",""),",",""),";",""),":",""),"!",""),"?",""),"""",""),"'",""),"’",""),"“",""),"”","")))) | Q7: =IF($A7="","",LOWER(TRIM(SUBSTITUTE(SUBSTITUTE(SUBSTITUTE(SUBSTITUTE(SUBSTITUTE(SUBSTITUTE(SUBSTITUTE(SUBSTITUTE(SUBSTITUTE(SUBSTITUTE(SUBSTITUTE(G7,".",""),",",""),";",""),":",""),"!",""),"?",""),"""",""),"'",""),"’",""),"“",""),"”","")))) | R7: =IF($A7="","",LEN(O7)) | S7: =IF($A7="","",IF(O7="",0,LEN(O7)-LEN(SUBSTITUTE(O7," ",""))+1)) | T7: =IF($A7="","",IF(AND(O7<>"",OR(O7=M7,AND(N7<>"",ISNUMBER(FIND("|"&O7&"|","|"&N7&"|"))))),1,0)) | U7: =IF($A7="","",IF(AND(Q7<>"",OR(Q7=M7,AND(N7<>"",ISNUMBER(FIND("|"&Q7&"|","|"&N7&"|"))))),1,0)) | V7: =IF($A7="","",IF(P7=O7,1,0)) | W7: =IF($A7="","",IF(Q7=O7,1,0)) | X7: =IF(OR($A7="",$H7=""),"",IF(AND($H7=1,T7=1),"TA",IF(AND($H7=0,T7=1),"FA",IF($H7=1,"FR","TR")))) | Y7: =IF(OR($A7="",$H7=""),"",IF(AND($H7=1,U7=1),"TA",IF(AND($H7=0,U7=1),"FA",IF($H7=1,"FR","TR"))))
A8: E04 | B8: P2 | C8: Ferdinand Magellan | D8: magellan|f magellan | E8: Magellan | F8: Magellan | G8: Magellan | H8: 1 | I8: 0 | J8: 0 | K8: 0 | M8: =IF($A8="","",LOWER(TRIM(SUBSTITUTE(SUBSTITUTE(SUBSTITUTE(SUBSTITUTE(SUBSTITUTE(SUBSTITUTE(SUBSTITUTE(SUBSTITUTE(SUBSTITUTE(SUBSTITUTE(SUBSTITUTE(C8,".",""),",",""),";",""),":",""),"!",""),"?",""),"""",""),"'",""),"’",""),"“",""),"”","")))) | N8: =IF($A8="","",SUBSTITUTE(SUBSTITUTE(LOWER(TRIM(SUBSTITUTE(SUBSTITUTE(SUBSTITUTE(SUBSTITUTE(SUBSTITUTE(SUBSTITUTE(SUBSTITUTE(SUBSTITUTE(SUBSTITUTE(SUBSTITUTE(SUBSTITUTE(D8,".",""),",",""),";",""),":",""),"!",""),"?",""),"""",""),"'",""),"’",""),"“",""),"”","")))," |","|"),"| ","|")) | O8: =IF($A8="","",LOWER(TRIM(SUBSTITUTE(SUBSTITUTE(SUBSTITUTE(SUBSTITUTE(SUBSTITUTE(SUBSTITUTE(SUBSTITUTE(SUBSTITUTE(SUBSTITUTE(SUBSTITUTE(SUBSTITUTE(E8,".",""),",",""),";",""),":",""),"!",""),"?",""),"""",""),"'",""),"’",""),"“",""),"”","")))) | P8: =IF($A8="","",LOWER(TRIM(SUBSTITUTE(SUBSTITUTE(SUBSTITUTE(SUBSTITUTE(SUBSTITUTE(SUBSTITUTE(SUBSTITUTE(SUBSTITUTE(SUBSTITUTE(SUBSTITUTE(SUBSTITUTE(F8,".",""),",",""),";",""),":",""),"!",""),"?",""),"""",""),"'",""),"’",""),"“",""),"”","")))) | Q8: =IF($A8="","",LOWER(TRIM(SUBSTITUTE(SUBSTITUTE(SUBSTITUTE(SUBSTITUTE(SUBSTITUTE(SUBSTITUTE(SUBSTITUTE(SUBSTITUTE(SUBSTITUTE(SUBSTITUTE(SUBSTITUTE(G8,".",""),",",""),";",""),":",""),"!",""),"?",""),"""",""),"'",""),"’",""),"“",""),"”","")))) | R8: =IF($A8="","",LEN(O8)) | S8: =IF($A8="","",IF(O8="",0,LEN(O8)-LEN(SUBSTITUTE(O8," ",""))+1)) | T8: =IF($A8="","",IF(AND(O8<>"",OR(O8=M8,AND(N8<>"",ISNUMBER(FIND("|"&O8&"|","|"&N8&"|"))))),1,0)) | U8: =IF($A8="","",IF(AND(Q8<>"",OR(Q8=M8,AND(N8<>"",ISNUMBER(FIND("|"&Q8&"|","|"&N8&"|"))))),1,0)) | V8: =IF($A8="","",IF(P8=O8,1,0)) | W8: =IF($A8="","",IF(Q8=O8,1,0)) | X8: =IF(OR($A8="",$H8=""),"",IF(AND($H8=1,T8=1),"TA",IF(AND($H8=0,T8=1),"FA",IF($H8=1,"FR","TR")))) | Y8: =IF(OR($A8="",$H8=""),"",IF(AND($H8=1,U8=1),"TA",IF(AND($H8=0,U8=1),"FA",IF($H8=1,"FR","TR"))))
A9: E05 | B9: P2 | C9: meiosis | E9: mitosis | F9: mitosis | G9: mitosis | H9: 0 | I9: 0 | J9: 0 | K9: 0 | M9: =IF($A9="","",LOWER(TRIM(SUBSTITUTE(SUBSTITUTE(SUBSTITUTE(SUBSTITUTE(SUBSTITUTE(SUBSTITUTE(SUBSTITUTE(SUBSTITUTE(SUBSTITUTE(SUBSTITUTE(SUBSTITUTE(C9,".",""),",",""),";",""),":",""),"!",""),"?",""),"""",""),"'",""),"’",""),"“",""),"”","")))) | N9: =IF($A9="","",SUBSTITUTE(SUBSTITUTE(LOWER(TRIM(SUBSTITUTE(SUBSTITUTE(SUBSTITUTE(SUBSTITUTE(SUBSTITUTE(SUBSTITUTE(SUBSTITUTE(SUBSTITUTE(SUBSTITUTE(SUBSTITUTE(SUBSTITUTE(D9,".",""),",",""),";",""),":",""),"!",""),"?",""),"""",""),"'",""),"’",""),"“",""),"”","")))," |","|"),"| ","|")) | O9: =IF($A9="","",LOWER(TRIM(SUBSTITUTE(SUBSTITUTE(SUBSTITUTE(SUBSTITUTE(SUBSTITUTE(SUBSTITUTE(SUBSTITUTE(SUBSTITUTE(SUBSTITUTE(SUBSTITUTE(SUBSTITUTE(E9,".",""),",",""),";",""),":",""),"!",""),"?",""),"""",""),"'",""),"’",""),"“",""),"”","")))) | P9: =IF($A9="","",LOWER(TRIM(SUBSTITUTE(SUBSTITUTE(SUBSTITUTE(SUBSTITUTE(SUBSTITUTE(SUBSTITUTE(SUBSTITUTE(SUBSTITUTE(SUBSTITUTE(SUBSTITUTE(SUBSTITUTE(F9,".",""),",",""),";",""),":",""),"!",""),"?",""),"""",""),"'",""),"’",""),"“",""),"”","")))) | Q9: =IF($A9="","",LOWER(TRIM(SUBSTITUTE(SUBSTITUTE(SUBSTITUTE(SUBSTITUTE(SUBSTITUTE(SUBSTITUTE(SUBSTITUTE(SUBSTITUTE(SUBSTITUTE(SUBSTITUTE(SUBSTITUTE(G9,".",""),",",""),";",""),":",""),"!",""),"?",""),"""",""),"'",""),"’",""),"“",""),"”","")))) | R9: =IF($A9="","",LEN(O9)) | S9: =IF($A9="","",IF(O9="",0,LEN(O9)-LEN(SUBSTITUTE(O9," ",""))+1)) | T9: =IF($A9="","",IF(AND(O9<>"",OR(O9=M9,AND(N9<>"",ISNUMBER(FIND("|"&O9&"|","|"&N9&"|"))))),1,0)) | U9: =IF($A9="","",IF(AND(Q9<>"",OR(Q9=M9,AND(N9<>"",ISNUMBER(FIND("|"&Q9&"|","|"&N9&"|"))))),1,0)) | V9: =IF($A9="","",IF(P9=O9,1,0)) | W9: =IF($A9="","",IF(Q9=O9,1,0)) | X9: =IF(OR($A9="",$H9=""),"",IF(AND($H9=1,T9=1),"TA",IF(AND($H9=0,T9=1),"FA",IF($H9=1,"FR","TR")))) | Y9: =IF(OR($A9="",$H9=""),"",IF(AND($H9=1,U9=1),"TA",IF(AND($H9=0,U9=1),"FA",IF($H9=1,"FR","TR"))))
A10: E06 | B10: P2 | C10: osmosis | E10: osmosis | H10: 1 | I10: 1 | J10: 7 | K10: 1 | L10: Transcription error | M10: =IF($A10="","",LOWER(TRIM(SUBSTITUTE(SUBSTITUTE(SUBSTITUTE(SUBSTITUTE(SUBSTITUTE(SUBSTITUTE(SUBSTITUTE(SUBSTITUTE(SUBSTITUTE(SUBSTITUTE(SUBSTITUTE(C10,".",""),",",""),";",""),":",""),"!",""),"?",""),"""",""),"'",""),"’",""),"“",""),"”","")))) | N10: =IF($A10="","",SUBSTITUTE(SUBSTITUTE(LOWER(TRIM(SUBSTITUTE(SUBSTITUTE(SUBSTITUTE(SUBSTITUTE(SUBSTITUTE(SUBSTITUTE(SUBSTITUTE(SUBSTITUTE(SUBSTITUTE(SUBSTITUTE(SUBSTITUTE(D10,".",""),",",""),";",""),":",""),"!",""),"?",""),"""",""),"'",""),"’",""),"“",""),"”","")))," |","|"),"| ","|")) | O10: =IF($A10="","",LOWER(TRIM(SUBSTITUTE(SUBSTITUTE(SUBSTITUTE(SUBSTITUTE(SUBSTITUTE(SUBSTITUTE(SUBSTITUTE(SUBSTITUTE(SUBSTITUTE(SUBSTITUTE(SUBSTITUTE(E10,".",""),",",""),";",""),":",""),"!",""),"?",""),"""",""),"'",""),"’",""),"“",""),"”","")))) | P10: =IF($A10="","",LOWER(TRIM(SUBSTITUTE(SUBSTITUTE(SUBSTITUTE(SUBSTITUTE(SUBSTITUTE(SUBSTITUTE(SUBSTITUTE(SUBSTITUTE(SUBSTITUTE(SUBSTITUTE(SUBSTITUTE(F10,".",""),",",""),";",""),":",""),"!",""),"?",""),"""",""),"'",""),"’",""),"“",""),"”","")))) | Q10: =IF($A10="","",LOWER(TRIM(SUBSTITUTE(SUBSTITUTE(SUBSTITUTE(SUBSTITUTE(SUBSTITUTE(SUBSTITUTE(SUBSTITUTE(SUBSTITUTE(SUBSTITUTE(SUBSTITUTE(SUBSTITUTE(G10,".",""),",",""),";",""),":",""),"!",""),"?",""),"""",""),"'",""),"’",""),"“",""),"”","")))) | R10: =IF($A10="","",LEN(O10)) | S10: =IF($A10="","",IF(O10="",0,LEN(O10)-LEN(SUBSTITUTE(O10," ",""))+1)) | T10: =IF($A10="","",IF(AND(O10<>"",OR(O10=M10,AND(N10<>"",ISNUMBER(FIND("|"&O10&"|","|"&N10&"|"))))),1,0)) | U10: =IF($A10="","",IF(AND(Q10<>"",OR(Q10=M10,AND(N10<>"",ISNUMBER(FIND("|"&Q10&"|","|"&N10&"|"))))),1,0)) | V10: =IF($A10="","",IF(P10=O10,1,0)) | W10: =IF($A10="","",IF(Q10=O10,1,0)) | X10: =IF(OR($A10="",$H10=""),"",IF(AND($H10=1,T10=1),"TA",IF(AND($H10=0,T10=1),"FA",IF($H10=1,"FR","TR")))) | Y10: =IF(OR($A10="",$H10=""),"",IF(AND($H10=1,U10=1),"TA",IF(AND($H10=0,U10=1),"FA",IF($H10=1,"FR","TR"))))
A11: E07 | B11: P3 | C11: supply and demand | E11: supply and demand | F11: supply and demond | G11: supply and demond | H11: 1 | I11: 0 | J11: 1 | K11: 1 | L11: Transcription error | M11: =IF($A11="","",LOWER(TRIM(SUBSTITUTE(SUBSTITUTE(SUBSTITUTE(SUBSTITUTE(SUBSTITUTE(SUBSTITUTE(SUBSTITUTE(SUBSTITUTE(SUBSTITUTE(SUBSTITUTE(SUBSTITUTE(C11,".",""),",",""),";",""),":",""),"!",""),"?",""),"""",""),"'",""),"’",""),"“",""),"”","")))) | N11: =IF($A11="","",SUBSTITUTE(SUBSTITUTE(LOWER(TRIM(SUBSTITUTE(SUBSTITUTE(SUBSTITUTE(SUBSTITUTE(SUBSTITUTE(SUBSTITUTE(SUBSTITUTE(SUBSTITUTE(SUBSTITUTE(SUBSTITUTE(SUBSTITUTE(D11,".",""),",",""),";",""),":",""),"!",""),"?",""),"""",""),"'",""),"’",""),"“",""),"”","")))," |","|"),"| ","|")) | O11: =IF($A11="","",LOWER(TRIM(SUBSTITUTE(SUBSTITUTE(SUBSTITUTE(SUBSTITUTE(SUBSTITUTE(SUBSTITUTE(SUBSTITUTE(SUBSTITUTE(SUBSTITUTE(SUBSTITUTE(SUBSTITUTE(E11,".",""),",",""),";",""),":",""),"!",""),"?",""),"""",""),"'",""),"’",""),"“",""),"”","")))) | P11: =IF($A11="","",LOWER(TRIM(SUBSTITUTE(SUBSTITUTE(SUBSTITUTE(SUBSTITUTE(SUBSTITUTE(SUBSTITUTE(SUBSTITUTE(SUBSTITUTE(SUBSTITUTE(SUBSTITUTE(SUBSTITUTE(F11,".",""),",",""),";",""),":",""),"!",""),"?",""),"""",""),"'",""),"’",""),"“",""),"”","")))) | Q11: =IF($A11="","",LOWER(TRIM(SUBSTITUTE(SUBSTITUTE(SUBSTITUTE(SUBSTITUTE(SUBSTITUTE(SUBSTITUTE(SUBSTITUTE(SUBSTITUTE(SUBSTITUTE(SUBSTITUTE(SUBSTITUTE(G11,".",""),",",""),";",""),":",""),"!",""),"?",""),"""",""),"'",""),"’",""),"“",""),"”","")))) | R11: =IF($A11="","",LEN(O11)) | S11: =IF($A11="","",IF(O11="",0,LEN(O11)-LEN(SUBSTITUTE(O11," ",""))+1)) | T11: =IF($A11="","",IF(AND(O11<>"",OR(O11=M11,AND(N11<>"",ISNUMBER(FIND("|"&O11&"|","|"&N11&"|"))))),1,0)) | U11: =IF($A11="","",IF(AND(Q11<>"",OR(Q11=M11,AND(N11<>"",ISNUMBER(FIND("|"&Q11&"|","|"&N11&"|"))))),1,0)) | V11: =IF($A11="","",IF(P11=O11,1,0)) | W11: =IF($A11="","",IF(Q11=O11,1,0)) | X11: =IF(OR($A11="",$H11=""),"",IF(AND($H11=1,T11=1),"TA",IF(AND($H11=0,T11=1),"FA",IF($H11=1,"FR","TR")))) | Y11: =IF(OR($A11="",$H11=""),"",IF(AND($H11=1,U11=1),"TA",IF(AND($H11=0,U11=1),"FA",IF($H11=1,"FR","TR"))))
A12: E08 | B12: P3 | C12: Rizal | D12: jose rizal|dr jose rizal | E12: Jose Rizal | F12: Jose Rizal | G12: Jose Rizal | H12: 1 | I12: 0 | J12: 0 | K12: 0 | M12: =IF($A12="","",LOWER(TRIM(SUBSTITUTE(SUBSTITUTE(SUBSTITUTE(SUBSTITUTE(SUBSTITUTE(SUBSTITUTE(SUBSTITUTE(SUBSTITUTE(SUBSTITUTE(SUBSTITUTE(SUBSTITUTE(C12,".",""),",",""),";",""),":",""),"!",""),"?",""),"""",""),"'",""),"’",""),"“",""),"”","")))) | N12: =IF($A12="","",SUBSTITUTE(SUBSTITUTE(LOWER(TRIM(SUBSTITUTE(SUBSTITUTE(SUBSTITUTE(SUBSTITUTE(SUBSTITUTE(SUBSTITUTE(SUBSTITUTE(SUBSTITUTE(SUBSTITUTE(SUBSTITUTE(SUBSTITUTE(D12,".",""),",",""),";",""),":",""),"!",""),"?",""),"""",""),"'",""),"’",""),"“",""),"”","")))," |","|"),"| ","|")) | O12: =IF($A12="","",LOWER(TRIM(SUBSTITUTE(SUBSTITUTE(SUBSTITUTE(SUBSTITUTE(SUBSTITUTE(SUBSTITUTE(SUBSTITUTE(SUBSTITUTE(SUBSTITUTE(SUBSTITUTE(SUBSTITUTE(E12,".",""),",",""),";",""),":",""),"!",""),"?",""),"""",""),"'",""),"’",""),"“",""),"”","")))) | P12: =IF($A12="","",LOWER(TRIM(SUBSTITUTE(SUBSTITUTE(SUBSTITUTE(SUBSTITUTE(SUBSTITUTE(SUBSTITUTE(SUBSTITUTE(SUBSTITUTE(SUBSTITUTE(SUBSTITUTE(SUBSTITUTE(F12,".",""),",",""),";",""),":",""),"!",""),"?",""),"""",""),"'",""),"’",""),"“",""),"”","")))) | Q12: =IF($A12="","",LOWER(TRIM(SUBSTITUTE(SUBSTITUTE(SUBSTITUTE(SUBSTITUTE(SUBSTITUTE(SUBSTITUTE(SUBSTITUTE(SUBSTITUTE(SUBSTITUTE(SUBSTITUTE(SUBSTITUTE(G12,".",""),",",""),";",""),":",""),"!",""),"?",""),"""",""),"'",""),"’",""),"“",""),"”","")))) | R12: =IF($A12="","",LEN(O12)) | S12: =IF($A12="","",IF(O12="",0,LEN(O12)-LEN(SUBSTITUTE(O12," ",""))+1)) | T12: =IF($A12="","",IF(AND(O12<>"",OR(O12=M12,AND(N12<>"",ISNUMBER(FIND("|"&O12&"|","|"&N12&"|"))))),1,0)) | U12: =IF($A12="","",IF(AND(Q12<>"",OR(Q12=M12,AND(N12<>"",ISNUMBER(FIND("|"&Q12&"|","|"&N12&"|"))))),1,0)) | V12: =IF($A12="","",IF(P12=O12,1,0)) | W12: =IF($A12="","",IF(Q12=O12,1,0)) | X12: =IF(OR($A12="",$H12=""),"",IF(AND($H12=1,T12=1),"TA",IF(AND($H12=0,T12=1),"FA",IF($H12=1,"FR","TR")))) | Y12: =IF(OR($A12="",$H12=""),"",IF(AND($H12=1,U12=1),"TA",IF(AND($H12=0,U12=1),"FA",IF($H12=1,"FR","TR"))))
A13: E09 | B13: P3 | C13: nitrogen | E13: oxygen | F13: oxygen | G13: oxygen | H13: 0 | I13: 0 | J13: 0 | K13: 0 | M13: =IF($A13="","",LOWER(TRIM(SUBSTITUTE(SUBSTITUTE(SUBSTITUTE(SUBSTITUTE(SUBSTITUTE(SUBSTITUTE(SUBSTITUTE(SUBSTITUTE(SUBSTITUTE(SUBSTITUTE(SUBSTITUTE(C13,".",""),",",""),";",""),":",""),"!",""),"?",""),"""",""),"'",""),"’",""),"“",""),"”","")))) | N13: =IF($A13="","",SUBSTITUTE(SUBSTITUTE(LOWER(TRIM(SUBSTITUTE(SUBSTITUTE(SUBSTITUTE(SUBSTITUTE(SUBSTITUTE(SUBSTITUTE(SUBSTITUTE(SUBSTITUTE(SUBSTITUTE(SUBSTITUTE(SUBSTITUTE(D13,".",""),",",""),";",""),":",""),"!",""),"?",""),"""",""),"'",""),"’",""),"“",""),"”","")))," |","|"),"| ","|")) | O13: =IF($A13="","",LOWER(TRIM(SUBSTITUTE(SUBSTITUTE(SUBSTITUTE(SUBSTITUTE(SUBSTITUTE(SUBSTITUTE(SUBSTITUTE(SUBSTITUTE(SUBSTITUTE(SUBSTITUTE(SUBSTITUTE(E13,".",""),",",""),";",""),":",""),"!",""),"?",""),"""",""),"'",""),"’",""),"“",""),"”","")))) | P13: =IF($A13="","",LOWER(TRIM(SUBSTITUTE(SUBSTITUTE(SUBSTITUTE(SUBSTITUTE(SUBSTITUTE(SUBSTITUTE(SUBSTITUTE(SUBSTITUTE(SUBSTITUTE(SUBSTITUTE(SUBSTITUTE(F13,".",""),",",""),";",""),":",""),"!",""),"?",""),"""",""),"'",""),"’",""),"“",""),"”","")))) | Q13: =IF($A13="","",LOWER(TRIM(SUBSTITUTE(SUBSTITUTE(SUBSTITUTE(SUBSTITUTE(SUBSTITUTE(SUBSTITUTE(SUBSTITUTE(SUBSTITUTE(SUBSTITUTE(SUBSTITUTE(SUBSTITUTE(G13,".",""),",",""),";",""),":",""),"!",""),"?",""),"""",""),"'",""),"’",""),"“",""),"”","")))) | R13: =IF($A13="","",LEN(O13)) | S13: =IF($A13="","",IF(O13="",0,LEN(O13)-LEN(SUBSTITUTE(O13," ",""))+1)) | T13: =IF($A13="","",IF(AND(O13<>"",OR(O13=M13,AND(N13<>"",ISNUMBER(FIND("|"&O13&"|","|"&N13&"|"))))),1,0)) | U13: =IF($A13="","",IF(AND(Q13<>"",OR(Q13=M13,AND(N13<>"",ISNUMBER(FIND("|"&Q13&"|","|"&N13&"|"))))),1,0)) | V13: =IF($A13="","",IF(P13=O13,1,0)) | W13: =IF($A13="","",IF(Q13=O13,1,0)) | X13: =IF(OR($A13="",$H13=""),"",IF(AND($H13=1,T13=1),"TA",IF(AND($H13=0,T13=1),"FA",IF($H13=1,"FR","TR")))) | Y13: =IF(OR($A13="",$H13=""),"",IF(AND($H13=1,U13=1),"TA",IF(AND($H13=0,U13=1),"FA",IF($H13=1,"FR","TR"))))
A14: E10 | B14: P4 | C14: sun | E14: the sun | F14: the sun | G14: the sun | H14: 1 | I14: 0 | J14: 0 | K14: 0 | L14: Spelling variant or synonym not on list | M14: =IF($A14="","",LOWER(TRIM(SUBSTITUTE(SUBSTITUTE(SUBSTITUTE(SUBSTITUTE(SUBSTITUTE(SUBSTITUTE(SUBSTITUTE(SUBSTITUTE(SUBSTITUTE(SUBSTITUTE(SUBSTITUTE(C14,".",""),",",""),";",""),":",""),"!",""),"?",""),"""",""),"'",""),"’",""),"“",""),"”","")))) | N14: =IF($A14="","",SUBSTITUTE(SUBSTITUTE(LOWER(TRIM(SUBSTITUTE(SUBSTITUTE(SUBSTITUTE(SUBSTITUTE(SUBSTITUTE(SUBSTITUTE(SUBSTITUTE(SUBSTITUTE(SUBSTITUTE(SUBSTITUTE(SUBSTITUTE(D14,".",""),",",""),";",""),":",""),"!",""),"?",""),"""",""),"'",""),"’",""),"“",""),"”","")))," |","|"),"| ","|")) | O14: =IF($A14="","",LOWER(TRIM(SUBSTITUTE(SUBSTITUTE(SUBSTITUTE(SUBSTITUTE(SUBSTITUTE(SUBSTITUTE(SUBSTITUTE(SUBSTITUTE(SUBSTITUTE(SUBSTITUTE(SUBSTITUTE(E14,".",""),",",""),";",""),":",""),"!",""),"?",""),"""",""),"'",""),"’",""),"“",""),"”","")))) | P14: =IF($A14="","",LOWER(TRIM(SUBSTITUTE(SUBSTITUTE(SUBSTITUTE(SUBSTITUTE(SUBSTITUTE(SUBSTITUTE(SUBSTITUTE(SUBSTITUTE(SUBSTITUTE(SUBSTITUTE(SUBSTITUTE(F14,".",""),",",""),";",""),":",""),"!",""),"?",""),"""",""),"'",""),"’",""),"“",""),"”","")))) | Q14: =IF($A14="","",LOWER(TRIM(SUBSTITUTE(SUBSTITUTE(SUBSTITUTE(SUBSTITUTE(SUBSTITUTE(SUBSTITUTE(SUBSTITUTE(SUBSTITUTE(SUBSTITUTE(SUBSTITUTE(SUBSTITUTE(G14,".",""),",",""),";",""),":",""),"!",""),"?",""),"""",""),"'",""),"’",""),"“",""),"”","")))) | R14: =IF($A14="","",LEN(O14)) | S14: =IF($A14="","",IF(O14="",0,LEN(O14)-LEN(SUBSTITUTE(O14," ",""))+1)) | T14: =IF($A14="","",IF(AND(O14<>"",OR(O14=M14,AND(N14<>"",ISNUMBER(FIND("|"&O14&"|","|"&N14&"|"))))),1,0)) | U14: =IF($A14="","",IF(AND(Q14<>"",OR(Q14=M14,AND(N14<>"",ISNUMBER(FIND("|"&Q14&"|","|"&N14&"|"))))),1,0)) | V14: =IF($A14="","",IF(P14=O14,1,0)) | W14: =IF($A14="","",IF(Q14=O14,1,0)) | X14: =IF(OR($A14="",$H14=""),"",IF(AND($H14=1,T14=1),"TA",IF(AND($H14=0,T14=1),"FA",IF($H14=1,"FR","TR")))) | Y14: =IF(OR($A14="",$H14=""),"",IF(AND($H14=1,U14=1),"TA",IF(AND($H14=0,U14=1),"FA",IF($H14=1,"FR","TR"))))
M15: =IF($A15="","",LOWER(TRIM(SUBSTITUTE(SUBSTITUTE(SUBSTITUTE(SUBSTITUTE(SUBSTITUTE(SUBSTITUTE(SUBSTITUTE(SUBSTITUTE(SUBSTITUTE(SUBSTITUTE(SUBSTITUTE(C15,".",""),",",""),";",""),":",""),"!",""),"?",""),"""",""),"'",""),"’",""),"“",""),"”","")))) | N15: =IF($A15="","",SUBSTITUTE(SUBSTITUTE(LOWER(TRIM(SUBSTITUTE(SUBSTITUTE(SUBSTITUTE(SUBSTITUTE(SUBSTITUTE(SUBSTITUTE(SUBSTITUTE(SUBSTITUTE(SUBSTITUTE(SUBSTITUTE(SUBSTITUTE(D15,".",""),",",""),";",""),":",""),"!",""),"?",""),"""",""),"'",""),"’",""),"“",""),"”","")))," |","|"),"| ","|")) | O15: =IF($A15="","",LOWER(TRIM(SUBSTITUTE(SUBSTITUTE(SUBSTITUTE(SUBSTITUTE(SUBSTITUTE(SUBSTITUTE(SUBSTITUTE(SUBSTITUTE(SUBSTITUTE(SUBSTITUTE(SUBSTITUTE(E15,".",""),",",""),";",""),":",""),"!",""),"?",""),"""",""),"'",""),"’",""),"“",""),"”","")))) | P15: =IF($A15="","",LOWER(TRIM(SUBSTITUTE(SUBSTITUTE(SUBSTITUTE(SUBSTITUTE(SUBSTITUTE(SUBSTITUTE(SUBSTITUTE(SUBSTITUTE(SUBSTITUTE(SUBSTITUTE(SUBSTITUTE(F15,".",""),",",""),";",""),":",""),"!",""),"?",""),"""",""),"'",""),"’",""),"“",""),"”","")))) | Q15: =IF($A15="","",LOWER(TRIM(SUBSTITUTE(SUBSTITUTE(SUBSTITUTE(SUBSTITUTE(SUBSTITUTE(SUBSTITUTE(SUBSTITUTE(SUBSTITUTE(SUBSTITUTE(SUBSTITUTE(SUBSTITUTE(G15,".",""),",",""),";",""),":",""),"!",""),"?",""),"""",""),"'",""),"’",""),"“",""),"”","")))) | R15: =IF($A15="","",LEN(O15)) | S15: =IF($A15="","",IF(O15="",0,LEN(O15)-LEN(SUBSTITUTE(O15," ",""))+1)) | T15: =IF($A15="","",IF(AND(O15<>"",OR(O15=M15,AND(N15<>"",ISNUMBER(FIND("|"&O15&"|","|"&N15&"|"))))),1,0)) | U15: =IF($A15="","",IF(AND(Q15<>"",OR(Q15=M15,AND(N15<>"",ISNUMBER(FIND("|"&Q15&"|","|"&N15&"|"))))),1,0)) | V15: =IF($A15="","",IF(P15=O15,1,0)) | W15: =IF($A15="","",IF(Q15=O15,1,0)) | X15: =IF(OR($A15="",$H15=""),"",IF(AND($H15=1,T15=1),"TA",IF(AND($H15=0,T15=1),"FA",IF($H15=1,"FR","TR")))) | Y15: =IF(OR($A15="",$H15=""),"",IF(AND($H15=1,U15=1),"TA",IF(AND($H15=0,U15=1),"FA",IF($H15=1,"FR","TR"))))
M16: =IF($A16="","",LOWER(TRIM(SUBSTITUTE(SUBSTITUTE(SUBSTITUTE(SUBSTITUTE(SUBSTITUTE(SUBSTITUTE(SUBSTITUTE(SUBSTITUTE(SUBSTITUTE(SUBSTITUTE(SUBSTITUTE(C16,".",""),",",""),";",""),":",""),"!",""),"?",""),"""",""),"'",""),"’",""),"“",""),"”","")))) | N16: =IF($A16="","",SUBSTITUTE(SUBSTITUTE(LOWER(TRIM(SUBSTITUTE(SUBSTITUTE(SUBSTITUTE(SUBSTITUTE(SUBSTITUTE(SUBSTITUTE(SUBSTITUTE(SUBSTITUTE(SUBSTITUTE(SUBSTITUTE(SUBSTITUTE(D16,".",""),",",""),";",""),":",""),"!",""),"?",""),"""",""),"'",""),"’",""),"“",""),"”","")))," |","|"),"| ","|")) | O16: =IF($A16="","",LOWER(TRIM(SUBSTITUTE(SUBSTITUTE(SUBSTITUTE(SUBSTITUTE(SUBSTITUTE(SUBSTITUTE(SUBSTITUTE(SUBSTITUTE(SUBSTITUTE(SUBSTITUTE(SUBSTITUTE(E16,".",""),",",""),";",""),":",""),"!",""),"?",""),"""",""),"'",""),"’",""),"“",""),"”","")))) | P16: =IF($A16="","",LOWER(TRIM(SUBSTITUTE(SUBSTITUTE(SUBSTITUTE(SUBSTITUTE(SUBSTITUTE(SUBSTITUTE(SUBSTITUTE(SUBSTITUTE(SUBSTITUTE(SUBSTITUTE(SUBSTITUTE(F16,".",""),",",""),";",""),":",""),"!",""),"?",""),"""",""),"'",""),"’",""),"“",""),"”","")))) | Q16: =IF($A16="","",LOWER(TRIM(SUBSTITUTE(SUBSTITUTE(SUBSTITUTE(SUBSTITUTE(SUBSTITUTE(SUBSTITUTE(SUBSTITUTE(SUBSTITUTE(SUBSTITUTE(SUBSTITUTE(SUBSTITUTE(G16,".",""),",",""),";",""),":",""),"!",""),"?",""),"""",""),"'",""),"’",""),"“",""),"”","")))) | R16: =IF($A16="","",LEN(O16)) | S16: =IF($A16="","",IF(O16="",0,LEN(O16)-LEN(SUBSTITUTE(O16," ",""))+1)) | T16: =IF($A16="","",IF(AND(O16<>"",OR(O16=M16,AND(N16<>"",ISNUMBER(FIND("|"&O16&"|","|"&N16&"|"))))),1,0)) | U16: =IF($A16="","",IF(AND(Q16<>"",OR(Q16=M16,AND(N16<>"",ISNUMBER(FIND("|"&Q16&"|","|"&N16&"|"))))),1,0)) | V16: =IF($A16="","",IF(P16=O16,1,0)) | W16: =IF($A16="","",IF(Q16=O16,1,0)) | X16: =IF(OR($A16="",$H16=""),"",IF(AND($H16=1,T16=1),"TA",IF(AND($H16=0,T16=1),"FA",IF($H16=1,"FR","TR")))) | Y16: =IF(OR($A16="",$H16=""),"",IF(AND($H16=1,U16=1),"TA",IF(AND($H16=0,U16=1),"FA",IF($H16=1,"FR","TR"))))
M17: =IF($A17="","",LOWER(TRIM(SUBSTITUTE(SUBSTITUTE(SUBSTITUTE(SUBSTITUTE(SUBSTITUTE(SUBSTITUTE(SUBSTITUTE(SUBSTITUTE(SUBSTITUTE(SUBSTITUTE(SUBSTITUTE(C17,".",""),",",""),";",""),":",""),"!",""),"?",""),"""",""),"'",""),"’",""),"“",""),"”","")))) | N17: =IF($A17="","",SUBSTITUTE(SUBSTITUTE(LOWER(TRIM(SUBSTITUTE(SUBSTITUTE(SUBSTITUTE(SUBSTITUTE(SUBSTITUTE(SUBSTITUTE(SUBSTITUTE(SUBSTITUTE(SUBSTITUTE(SUBSTITUTE(SUBSTITUTE(D17,".",""),",",""),";",""),":",""),"!",""),"?",""),"""",""),"'",""),"’",""),"“",""),"”","")))," |","|"),"| ","|")) | O17: =IF($A17="","",LOWER(TRIM(SUBSTITUTE(SUBSTITUTE(SUBSTITUTE(SUBSTITUTE(SUBSTITUTE(SUBSTITUTE(SUBSTITUTE(SUBSTITUTE(SUBSTITUTE(SUBSTITUTE(SUBSTITUTE(E17,".",""),",",""),";",""),":",""),"!",""),"?",""),"""",""),"'",""),"’",""),"“",""),"”","")))) | P17: =IF($A17="","",LOWER(TRIM(SUBSTITUTE(SUBSTITUTE(SUBSTITUTE(SUBSTITUTE(SUBSTITUTE(SUBSTITUTE(SUBSTITUTE(SUBSTITUTE(SUBSTITUTE(SUBSTITUTE(SUBSTITUTE(F17,".",""),",",""),";",""),":",""),"!",""),"?",""),"""",""),"'",""),"’",""),"“",""),"”","")))) | Q17: =IF($A17="","",LOWER(TRIM(SUBSTITUTE(SUBSTITUTE(SUBSTITUTE(SUBSTITUTE(SUBSTITUTE(SUBSTITUTE(SUBSTITUTE(SUBSTITUTE(SUBSTITUTE(SUBSTITUTE(SUBSTITUTE(G17,".",""),",",""),";",""),":",""),"!",""),"?",""),"""",""),"'",""),"’",""),"“",""),"”","")))) | R17: =IF($A17="","",LEN(O17)) | S17: =IF($A17="","",IF(O17="",0,LEN(O17)-LEN(SUBSTITUTE(O17," ",""))+1)) | T17: =IF($A17="","",IF(AND(O17<>"",OR(O17=M17,AND(N17<>"",ISNUMBER(FIND("|"&O17&"|","|"&N17&"|"))))),1,0)) | U17: =IF($A17="","",IF(AND(Q17<>"",OR(Q17=M17,AND(N17<>"",ISNUMBER(FIND("|"&Q17&"|","|"&N17&"|"))))),1,0)) | V17: =IF($A17="","",IF(P17=O17,1,0)) | W17: =IF($A17="","",IF(Q17=O17,1,0)) | X17: =IF(OR($A17="",$H17=""),"",IF(AND($H17=1,T17=1),"TA",IF(AND($H17=0,T17=1),"FA",IF($H17=1,"FR","TR")))) | Y17: =IF(OR($A17="",$H17=""),"",IF(AND($H17=1,U17=1),"TA",IF(AND($H17=0,U17=1),"FA",IF($H17=1,"FR","TR"))))
M18: =IF($A18="","",LOWER(TRIM(SUBSTITUTE(SUBSTITUTE(SUBSTITUTE(SUBSTITUTE(SUBSTITUTE(SUBSTITUTE(SUBSTITUTE(SUBSTITUTE(SUBSTITUTE(SUBSTITUTE(SUBSTITUTE(C18,".",""),",",""),";",""),":",""),"!",""),"?",""),"""",""),"'",""),"’",""),"“",""),"”","")))) | N18: =IF($A18="","",SUBSTITUTE(SUBSTITUTE(LOWER(TRIM(SUBSTITUTE(SUBSTITUTE(SUBSTITUTE(SUBSTITUTE(SUBSTITUTE(SUBSTITUTE(SUBSTITUTE(SUBSTITUTE(SUBSTITUTE(SUBSTITUTE(SUBSTITUTE(D18,".",""),",",""),";",""),":",""),"!",""),"?",""),"""",""),"'",""),"’",""),"“",""),"”","")))," |","|"),"| ","|")) | O18: =IF($A18="","",LOWER(TRIM(SUBSTITUTE(SUBSTITUTE(SUBSTITUTE(SUBSTITUTE(SUBSTITUTE(SUBSTITUTE(SUBSTITUTE(SUBSTITUTE(SUBSTITUTE(SUBSTITUTE(SUBSTITUTE(E18,".",""),",",""),";",""),":",""),"!",""),"?",""),"""",""),"'",""),"’",""),"“",""),"”","")))) | P18: =IF($A18="","",LOWER(TRIM(SUBSTITUTE(SUBSTITUTE(SUBSTITUTE(SUBSTITUTE(SUBSTITUTE(SUBSTITUTE(SUBSTITUTE(SUBSTITUTE(SUBSTITUTE(SUBSTITUTE(SUBSTITUTE(F18,".",""),",",""),";",""),":",""),"!",""),"?",""),"""",""),"'",""),"’",""),"“",""),"”","")))) | Q18: =IF($A18="","",LOWER(TRIM(SUBSTITUTE(SUBSTITUTE(SUBSTITUTE(SUBSTITUTE(SUBSTITUTE(SUBSTITUTE(SUBSTITUTE(SUBSTITUTE(SUBSTITUTE(SUBSTITUTE(SUBSTITUTE(G18,".",""),",",""),";",""),":",""),"!",""),"?",""),"""",""),"'",""),"’",""),"“",""),"”","")))) | R18: =IF($A18="","",LEN(O18)) | S18: =IF($A18="","",IF(O18="",0,LEN(O18)-LEN(SUBSTITUTE(O18," ",""))+1)) | T18: =IF($A18="","",IF(AND(O18<>"",OR(O18=M18,AND(N18<>"",ISNUMBER(FIND("|"&O18&"|","|"&N18&"|"))))),1,0)) | U18: =IF($A18="","",IF(AND(Q18<>"",OR(Q18=M18,AND(N18<>"",ISNUMBER(FIND("|"&Q18&"|","|"&N18&"|"))))),1,0)) | V18: =IF($A18="","",IF(P18=O18,1,0)) | W18: =IF($A18="","",IF(Q18=O18,1,0)) | X18: =IF(OR($A18="",$H18=""),"",IF(AND($H18=1,T18=1),"TA",IF(AND($H18=0,T18=1),"FA",IF($H18=1,"FR","TR")))) | Y18: =IF(OR($A18="",$H18=""),"",IF(AND($H18=1,U18=1),"TA",IF(AND($H18=0,U18=1),"FA",IF($H18=1,"FR","TR"))))
M19: =IF($A19="","",LOWER(TRIM(SUBSTITUTE(SUBSTITUTE(SUBSTITUTE(SUBSTITUTE(SUBSTITUTE(SUBSTITUTE(SUBSTITUTE(SUBSTITUTE(SUBSTITUTE(SUBSTITUTE(SUBSTITUTE(C19,".",""),",",""),";",""),":",""),"!",""),"?",""),"""",""),"'",""),"’",""),"“",""),"”","")))) | N19: =IF($A19="","",SUBSTITUTE(SUBSTITUTE(LOWER(TRIM(SUBSTITUTE(SUBSTITUTE(SUBSTITUTE(SUBSTITUTE(SUBSTITUTE(SUBSTITUTE(SUBSTITUTE(SUBSTITUTE(SUBSTITUTE(SUBSTITUTE(SUBSTITUTE(D19,".",""),",",""),";",""),":",""),"!",""),"?",""),"""",""),"'",""),"’",""),"“",""),"”","")))," |","|"),"| ","|")) | O19: =IF($A19="","",LOWER(TRIM(SUBSTITUTE(SUBSTITUTE(SUBSTITUTE(SUBSTITUTE(SUBSTITUTE(SUBSTITUTE(SUBSTITUTE(SUBSTITUTE(SUBSTITUTE(SUBSTITUTE(SUBSTITUTE(E19,".",""),",",""),";",""),":",""),"!",""),"?",""),"""",""),"'",""),"’",""),"“",""),"”","")))) | P19: =IF($A19="","",LOWER(TRIM(SUBSTITUTE(SUBSTITUTE(SUBSTITUTE(SUBSTITUTE(SUBSTITUTE(SUBSTITUTE(SUBSTITUTE(SUBSTITUTE(SUBSTITUTE(SUBSTITUTE(SUBSTITUTE(F19,".",""),",",""),";",""),":",""),"!",""),"?",""),"""",""),"'",""),"’",""),"“",""),"”","")))) | Q19: =IF($A19="","",LOWER(TRIM(SUBSTITUTE(SUBSTITUTE(SUBSTITUTE(SUBSTITUTE(SUBSTITUTE(SUBSTITUTE(SUBSTITUTE(SUBSTITUTE(SUBSTITUTE(SUBSTITUTE(SUBSTITUTE(G19,".",""),",",""),";",""),":",""),"!",""),"?",""),"""",""),"'",""),"’",""),"“",""),"”","")))) | R19: =IF($A19="","",LEN(O19)) | S19: =IF($A19="","",IF(O19="",0,LEN(O19)-LEN(SUBSTITUTE(O19," ",""))+1)) | T19: =IF($A19="","",IF(AND(O19<>"",OR(O19=M19,AND(N19<>"",ISNUMBER(FIND("|"&O19&"|","|"&N19&"|"))))),1,0)) | U19: =IF($A19="","",IF(AND(Q19<>"",OR(Q19=M19,AND(N19<>"",ISNUMBER(FIND("|"&Q19&"|","|"&N19&"|"))))),1,0)) | V19: =IF($A19="","",IF(P19=O19,1,0)) | W19: =IF($A19="","",IF(Q19=O19,1,0)) | X19: =IF(OR($A19="",$H19=""),"",IF(AND($H19=1,T19=1),"TA",IF(AND($H19=0,T19=1),"FA",IF($H19=1,"FR","TR")))) | Y19: =IF(OR($A19="",$H19=""),"",IF(AND($H19=1,U19=1),"TA",IF(AND($H19=0,U19=1),"FA",IF($H19=1,"FR","TR"))))
M20: =IF($A20="","",LOWER(TRIM(SUBSTITUTE(SUBSTITUTE(SUBSTITUTE(SUBSTITUTE(SUBSTITUTE(SUBSTITUTE(SUBSTITUTE(SUBSTITUTE(SUBSTITUTE(SUBSTITUTE(SUBSTITUTE(C20,".",""),",",""),";",""),":",""),"!",""),"?",""),"""",""),"'",""),"’",""),"“",""),"”","")))) | N20: =IF($A20="","",SUBSTITUTE(SUBSTITUTE(LOWER(TRIM(SUBSTITUTE(SUBSTITUTE(SUBSTITUTE(SUBSTITUTE(SUBSTITUTE(SUBSTITUTE(SUBSTITUTE(SUBSTITUTE(SUBSTITUTE(SUBSTITUTE(SUBSTITUTE(D20,".",""),",",""),";",""),":",""),"!",""),"?",""),"""",""),"'",""),"’",""),"“",""),"”","")))," |","|"),"| ","|")) | O20: =IF($A20="","",LOWER(TRIM(SUBSTITUTE(SUBSTITUTE(SUBSTITUTE(SUBSTITUTE(SUBSTITUTE(SUBSTITUTE(SUBSTITUTE(SUBSTITUTE(SUBSTITUTE(SUBSTITUTE(SUBSTITUTE(E20,".",""),",",""),";",""),":",""),"!",""),"?",""),"""",""),"'",""),"’",""),"“",""),"”","")))) | P20: =IF($A20="","",LOWER(TRIM(SUBSTITUTE(SUBSTITUTE(SUBSTITUTE(SUBSTITUTE(SUBSTITUTE(SUBSTITUTE(SUBSTITUTE(SUBSTITUTE(SUBSTITUTE(SUBSTITUTE(SUBSTITUTE(F20,".",""),",",""),";",""),":",""),"!",""),"?",""),"""",""),"'",""),"’",""),"“",""),"”","")))) | Q20: =IF($A20="","",LOWER(TRIM(SUBSTITUTE(SUBSTITUTE(SUBSTITUTE(SUBSTITUTE(SUBSTITUTE(SUBSTITUTE(SUBSTITUTE(SUBSTITUTE(SUBSTITUTE(SUBSTITUTE(SUBSTITUTE(G20,".",""),",",""),";",""),":",""),"!",""),"?",""),"""",""),"'",""),"’",""),"“",""),"”","")))) | R20: =IF($A20="","",LEN(O20)) | S20: =IF($A20="","",IF(O20="",0,LEN(O20)-LEN(SUBSTITUTE(O20," ",""))+1)) | T20: =IF($A20="","",IF(AND(O20<>"",OR(O20=M20,AND(N20<>"",ISNUMBER(FIND("|"&O20&"|","|"&N20&"|"))))),1,0)) | U20: =IF($A20="","",IF(AND(Q20<>"",OR(Q20=M20,AND(N20<>"",ISNUMBER(FIND("|"&Q20&"|","|"&N20&"|"))))),1,0)) | V20: =IF($A20="","",IF(P20=O20,1,0)) | W20: =IF($A20="","",IF(Q20=O20,1,0)) | X20: =IF(OR($A20="",$H20=""),"",IF(AND($H20=1,T20=1),"TA",IF(AND($H20=0,T20=1),"FA",IF($H20=1,"FR","TR")))) | Y20: =IF(OR($A20="",$H20=""),"",IF(AND($H20=1,U20=1),"TA",IF(AND($H20=0,U20=1),"FA",IF($H20=1,"FR","TR"))))
M21: =IF($A21="","",LOWER(TRIM(SUBSTITUTE(SUBSTITUTE(SUBSTITUTE(SUBSTITUTE(SUBSTITUTE(SUBSTITUTE(SUBSTITUTE(SUBSTITUTE(SUBSTITUTE(SUBSTITUTE(SUBSTITUTE(C21,".",""),",",""),";",""),":",""),"!",""),"?",""),"""",""),"'",""),"’",""),"“",""),"”","")))) | N21: =IF($A21="","",SUBSTITUTE(SUBSTITUTE(LOWER(TRIM(SUBSTITUTE(SUBSTITUTE(SUBSTITUTE(SUBSTITUTE(SUBSTITUTE(SUBSTITUTE(SUBSTITUTE(SUBSTITUTE(SUBSTITUTE(SUBSTITUTE(SUBSTITUTE(D21,".",""),",",""),";",""),":",""),"!",""),"?",""),"""",""),"'",""),"’",""),"“",""),"”","")))," |","|"),"| ","|")) | O21: =IF($A21="","",LOWER(TRIM(SUBSTITUTE(SUBSTITUTE(SUBSTITUTE(SUBSTITUTE(SUBSTITUTE(SUBSTITUTE(SUBSTITUTE(SUBSTITUTE(SUBSTITUTE(SUBSTITUTE(SUBSTITUTE(E21,".",""),",",""),";",""),":",""),"!",""),"?",""),"""",""),"'",""),"’",""),"“",""),"”","")))) | P21: =IF($A21="","",LOWER(TRIM(SUBSTITUTE(SUBSTITUTE(SUBSTITUTE(SUBSTITUTE(SUBSTITUTE(SUBSTITUTE(SUBSTITUTE(SUBSTITUTE(SUBSTITUTE(SUBSTITUTE(SUBSTITUTE(F21,".",""),",",""),";",""),":",""),"!",""),"?",""),"""",""),"'",""),"’",""),"“",""),"”","")))) | Q21: =IF($A21="","",LOWER(TRIM(SUBSTITUTE(SUBSTITUTE(SUBSTITUTE(SUBSTITUTE(SUBSTITUTE(SUBSTITUTE(SUBSTITUTE(SUBSTITUTE(SUBSTITUTE(SUBSTITUTE(SUBSTITUTE(G21,".",""),",",""),";",""),":",""),"!",""),"?",""),"""",""),"'",""),"’",""),"“",""),"”","")))) | R21: =IF($A21="","",LEN(O21)) | S21: =IF($A21="","",IF(O21="",0,LEN(O21)-LEN(SUBSTITUTE(O21," ",""))+1)) | T21: =IF($A21="","",IF(AND(O21<>"",OR(O21=M21,AND(N21<>"",ISNUMBER(FIND("|"&O21&"|","|"&N21&"|"))))),1,0)) | U21: =IF($A21="","",IF(AND(Q21<>"",OR(Q21=M21,AND(N21<>"",ISNUMBER(FIND("|"&Q21&"|","|"&N21&"|"))))),1,0)) | V21: =IF($A21="","",IF(P21=O21,1,0)) | W21: =IF($A21="","",IF(Q21=O21,1,0)) | X21: =IF(OR($A21="",$H21=""),"",IF(AND($H21=1,T21=1),"TA",IF(AND($H21=0,T21=1),"FA",IF($H21=1,"FR","TR")))) | Y21: =IF(OR($A21="",$H21=""),"",IF(AND($H21=1,U21=1),"TA",IF(AND($H21=0,U21=1),"FA",IF($H21=1,"FR","TR"))))
M22: =IF($A22="","",LOWER(TRIM(SUBSTITUTE(SUBSTITUTE(SUBSTITUTE(SUBSTITUTE(SUBSTITUTE(SUBSTITUTE(SUBSTITUTE(SUBSTITUTE(SUBSTITUTE(SUBSTITUTE(SUBSTITUTE(C22,".",""),",",""),";",""),":",""),"!",""),"?",""),"""",""),"'",""),"’",""),"“",""),"”","")))) | N22: =IF($A22="","",SUBSTITUTE(SUBSTITUTE(LOWER(TRIM(SUBSTITUTE(SUBSTITUTE(SUBSTITUTE(SUBSTITUTE(SUBSTITUTE(SUBSTITUTE(SUBSTITUTE(SUBSTITUTE(SUBSTITUTE(SUBSTITUTE(SUBSTITUTE(D22,".",""),",",""),";",""),":",""),"!",""),"?",""),"""",""),"'",""),"’",""),"“",""),"”","")))," |","|"),"| ","|")) | O22: =IF($A22="","",LOWER(TRIM(SUBSTITUTE(SUBSTITUTE(SUBSTITUTE(SUBSTITUTE(SUBSTITUTE(SUBSTITUTE(SUBSTITUTE(SUBSTITUTE(SUBSTITUTE(SUBSTITUTE(SUBSTITUTE(E22,".",""),",",""),";",""),":",""),"!",""),"?",""),"""",""),"'",""),"’",""),"“",""),"”","")))) | P22: =IF($A22="","",LOWER(TRIM(SUBSTITUTE(SUBSTITUTE(SUBSTITUTE(SUBSTITUTE(SUBSTITUTE(SUBSTITUTE(SUBSTITUTE(SUBSTITUTE(SUBSTITUTE(SUBSTITUTE(SUBSTITUTE(F22,".",""),",",""),";",""),":",""),"!",""),"?",""),"""",""),"'",""),"’",""),"“",""),"”","")))) | Q22: =IF($A22="","",LOWER(TRIM(SUBSTITUTE(SUBSTITUTE(SUBSTITUTE(SUBSTITUTE(SUBSTITUTE(SUBSTITUTE(SUBSTITUTE(SUBSTITUTE(SUBSTITUTE(SUBSTITUTE(SUBSTITUTE(G22,".",""),",",""),";",""),":",""),"!",""),"?",""),"""",""),"'",""),"’",""),"“",""),"”","")))) | R22: =IF($A22="","",LEN(O22)) | S22: =IF($A22="","",IF(O22="",0,LEN(O22)-LEN(SUBSTITUTE(O22," ",""))+1)) | T22: =IF($A22="","",IF(AND(O22<>"",OR(O22=M22,AND(N22<>"",ISNUMBER(FIND("|"&O22&"|","|"&N22&"|"))))),1,0)) | U22: =IF($A22="","",IF(AND(Q22<>"",OR(Q22=M22,AND(N22<>"",ISNUMBER(FIND("|"&Q22&"|","|"&N22&"|"))))),1,0)) | V22: =IF($A22="","",IF(P22=O22,1,0)) | W22: =IF($A22="","",IF(Q22=O22,1,0)) | X22: =IF(OR($A22="",$H22=""),"",IF(AND($H22=1,T22=1),"TA",IF(AND($H22=0,T22=1),"FA",IF($H22=1,"FR","TR")))) | Y22: =IF(OR($A22="",$H22=""),"",IF(AND($H22=1,U22=1),"TA",IF(AND($H22=0,U22=1),"FA",IF($H22=1,"FR","TR"))))
M23: =IF($A23="","",LOWER(TRIM(SUBSTITUTE(SUBSTITUTE(SUBSTITUTE(SUBSTITUTE(SUBSTITUTE(SUBSTITUTE(SUBSTITUTE(SUBSTITUTE(SUBSTITUTE(SUBSTITUTE(SUBSTITUTE(C23,".",""),",",""),";",""),":",""),"!",""),"?",""),"""",""),"'",""),"’",""),"“",""),"”","")))) | N23: =IF($A23="","",SUBSTITUTE(SUBSTITUTE(LOWER(TRIM(SUBSTITUTE(SUBSTITUTE(SUBSTITUTE(SUBSTITUTE(SUBSTITUTE(SUBSTITUTE(SUBSTITUTE(SUBSTITUTE(SUBSTITUTE(SUBSTITUTE(SUBSTITUTE(D23,".",""),",",""),";",""),":",""),"!",""),"?",""),"""",""),"'",""),"’",""),"“",""),"”","")))," |","|"),"| ","|")) | O23: =IF($A23="","",LOWER(TRIM(SUBSTITUTE(SUBSTITUTE(SUBSTITUTE(SUBSTITUTE(SUBSTITUTE(SUBSTITUTE(SUBSTITUTE(SUBSTITUTE(SUBSTITUTE(SUBSTITUTE(SUBSTITUTE(E23,".",""),",",""),";",""),":",""),"!",""),"?",""),"""",""),"'",""),"’",""),"“",""),"”","")))) | P23: =IF($A23="","",LOWER(TRIM(SUBSTITUTE(SUBSTITUTE(SUBSTITUTE(SUBSTITUTE(SUBSTITUTE(SUBSTITUTE(SUBSTITUTE(SUBSTITUTE(SUBSTITUTE(SUBSTITUTE(SUBSTITUTE(F23,".",""),",",""),";",""),":",""),"!",""),"?",""),"""",""),"'",""),"’",""),"“",""),"”","")))) | Q23: =IF($A23="","",LOWER(TRIM(SUBSTITUTE(SUBSTITUTE(SUBSTITUTE(SUBSTITUTE(SUBSTITUTE(SUBSTITUTE(SUBSTITUTE(SUBSTITUTE(SUBSTITUTE(SUBSTITUTE(SUBSTITUTE(G23,".",""),",",""),";",""),":",""),"!",""),"?",""),"""",""),"'",""),"’",""),"“",""),"”","")))) | R23: =IF($A23="","",LEN(O23)) | S23: =IF($A23="","",IF(O23="",0,LEN(O23)-LEN(SUBSTITUTE(O23," ",""))+1)) | T23: =IF($A23="","",IF(AND(O23<>"",OR(O23=M23,AND(N23<>"",ISNUMBER(FIND("|"&O23&"|","|"&N23&"|"))))),1,0)) | U23: =IF($A23="","",IF(AND(Q23<>"",OR(Q23=M23,AND(N23<>"",ISNUMBER(FIND("|"&Q23&"|","|"&N23&"|"))))),1,0)) | V23: =IF($A23="","",IF(P23=O23,1,0)) | W23: =IF($A23="","",IF(Q23=O23,1,0)) | X23: =IF(OR($A23="",$H23=""),"",IF(AND($H23=1,T23=1),"TA",IF(AND($H23=0,T23=1),"FA",IF($H23=1,"FR","TR")))) | Y23: =IF(OR($A23="",$H23=""),"",IF(AND($H23=1,U23=1),"TA",IF(AND($H23=0,U23=1),"FA",IF($H23=1,"FR","TR"))))
M24: =IF($A24="","",LOWER(TRIM(SUBSTITUTE(SUBSTITUTE(SUBSTITUTE(SUBSTITUTE(SUBSTITUTE(SUBSTITUTE(SUBSTITUTE(SUBSTITUTE(SUBSTITUTE(SUBSTITUTE(SUBSTITUTE(C24,".",""),",",""),";",""),":",""),"!",""),"?",""),"""",""),"'",""),"’",""),"“",""),"”","")))) | N24: =IF($A24="","",SUBSTITUTE(SUBSTITUTE(LOWER(TRIM(SUBSTITUTE(SUBSTITUTE(SUBSTITUTE(SUBSTITUTE(SUBSTITUTE(SUBSTITUTE(SUBSTITUTE(SUBSTITUTE(SUBSTITUTE(SUBSTITUTE(SUBSTITUTE(D24,".",""),",",""),";",""),":",""),"!",""),"?",""),"""",""),"'",""),"’",""),"“",""),"”","")))," |","|"),"| ","|")) | O24: =IF($A24="","",LOWER(TRIM(SUBSTITUTE(SUBSTITUTE(SUBSTITUTE(SUBSTITUTE(SUBSTITUTE(SUBSTITUTE(SUBSTITUTE(SUBSTITUTE(SUBSTITUTE(SUBSTITUTE(SUBSTITUTE(E24,".",""),",",""),";",""),":",""),"!",""),"?",""),"""",""),"'",""),"’",""),"“",""),"”","")))) | P24: =IF($A24="","",LOWER(TRIM(SUBSTITUTE(SUBSTITUTE(SUBSTITUTE(SUBSTITUTE(SUBSTITUTE(SUBSTITUTE(SUBSTITUTE(SUBSTITUTE(SUBSTITUTE(SUBSTITUTE(SUBSTITUTE(F24,".",""),",",""),";",""),":",""),"!",""),"?",""),"""",""),"'",""),"’",""),"“",""),"”","")))) | Q24: =IF($A24="","",LOWER(TRIM(SUBSTITUTE(SUBSTITUTE(SUBSTITUTE(SUBSTITUTE(SUBSTITUTE(SUBSTITUTE(SUBSTITUTE(SUBSTITUTE(SUBSTITUTE(SUBSTITUTE(SUBSTITUTE(G24,".",""),",",""),";",""),":",""),"!",""),"?",""),"""",""),"'",""),"’",""),"“",""),"”","")))) | R24: =IF($A24="","",LEN(O24)) | S24: =IF($A24="","",IF(O24="",0,LEN(O24)-LEN(SUBSTITUTE(O24," ",""))+1)) | T24: =IF($A24="","",IF(AND(O24<>"",OR(O24=M24,AND(N24<>"",ISNUMBER(FIND("|"&O24&"|","|"&N24&"|"))))),1,0)) | U24: =IF($A24="","",IF(AND(Q24<>"",OR(Q24=M24,AND(N24<>"",ISNUMBER(FIND("|"&Q24&"|","|"&N24&"|"))))),1,0)) | V24: =IF($A24="","",IF(P24=O24,1,0)) | W24: =IF($A24="","",IF(Q24=O24,1,0)) | X24: =IF(OR($A24="",$H24=""),"",IF(AND($H24=1,T24=1),"TA",IF(AND($H24=0,T24=1),"FA",IF($H24=1,"FR","TR")))) | Y24: =IF(OR($A24="",$H24=""),"",IF(AND($H24=1,U24=1),"TA",IF(AND($H24=0,U24=1),"FA",IF($H24=1,"FR","TR"))))
M25: =IF($A25="","",LOWER(TRIM(SUBSTITUTE(SUBSTITUTE(SUBSTITUTE(SUBSTITUTE(SUBSTITUTE(SUBSTITUTE(SUBSTITUTE(SUBSTITUTE(SUBSTITUTE(SUBSTITUTE(SUBSTITUTE(C25,".",""),",",""),";",""),":",""),"!",""),"?",""),"""",""),"'",""),"’",""),"“",""),"”","")))) | N25: =IF($A25="","",SUBSTITUTE(SUBSTITUTE(LOWER(TRIM(SUBSTITUTE(SUBSTITUTE(SUBSTITUTE(SUBSTITUTE(SUBSTITUTE(SUBSTITUTE(SUBSTITUTE(SUBSTITUTE(SUBSTITUTE(SUBSTITUTE(SUBSTITUTE(D25,".",""),",",""),";",""),":",""),"!",""),"?",""),"""",""),"'",""),"’",""),"“",""),"”","")))," |","|"),"| ","|")) | O25: =IF($A25="","",LOWER(TRIM(SUBSTITUTE(SUBSTITUTE(SUBSTITUTE(SUBSTITUTE(SUBSTITUTE(SUBSTITUTE(SUBSTITUTE(SUBSTITUTE(SUBSTITUTE(SUBSTITUTE(SUBSTITUTE(E25,".",""),",",""),";",""),":",""),"!",""),"?",""),"""",""),"'",""),"’",""),"“",""),"”","")))) | P25: =IF($A25="","",LOWER(TRIM(SUBSTITUTE(SUBSTITUTE(SUBSTITUTE(SUBSTITUTE(SUBSTITUTE(SUBSTITUTE(SUBSTITUTE(SUBSTITUTE(SUBSTITUTE(SUBSTITUTE(SUBSTITUTE(F25,".",""),",",""),";",""),":",""),"!",""),"?",""),"""",""),"'",""),"’",""),"“",""),"”","")))) | Q25: =IF($A25="","",LOWER(TRIM(SUBSTITUTE(SUBSTITUTE(SUBSTITUTE(SUBSTITUTE(SUBSTITUTE(SUBSTITUTE(SUBSTITUTE(SUBSTITUTE(SUBSTITUTE(SUBSTITUTE(SUBSTITUTE(G25,".",""),",",""),";",""),":",""),"!",""),"?",""),"""",""),"'",""),"’",""),"“",""),"”","")))) | R25: =IF($A25="","",LEN(O25)) | S25: =IF($A25="","",IF(O25="",0,LEN(O25)-LEN(SUBSTITUTE(O25," ",""))+1)) | T25: =IF($A25="","",IF(AND(O25<>"",OR(O25=M25,AND(N25<>"",ISNUMBER(FIND("|"&O25&"|","|"&N25&"|"))))),1,0)) | U25: =IF($A25="","",IF(AND(Q25<>"",OR(Q25=M25,AND(N25<>"",ISNUMBER(FIND("|"&Q25&"|","|"&N25&"|"))))),1,0)) | V25: =IF($A25="","",IF(P25=O25,1,0)) | W25: =IF($A25="","",IF(Q25=O25,1,0)) | X25: =IF(OR($A25="",$H25=""),"",IF(AND($H25=1,T25=1),"TA",IF(AND($H25=0,T25=1),"FA",IF($H25=1,"FR","TR")))) | Y25: =IF(OR($A25="",$H25=""),"",IF(AND($H25=1,U25=1),"TA",IF(AND($H25=0,U25=1),"FA",IF($H25=1,"FR","TR"))))
M26: =IF($A26="","",LOWER(TRIM(SUBSTITUTE(SUBSTITUTE(SUBSTITUTE(SUBSTITUTE(SUBSTITUTE(SUBSTITUTE(SUBSTITUTE(SUBSTITUTE(SUBSTITUTE(SUBSTITUTE(SUBSTITUTE(C26,".",""),",",""),";",""),":",""),"!",""),"?",""),"""",""),"'",""),"’",""),"“",""),"”","")))) | N26: =IF($A26="","",SUBSTITUTE(SUBSTITUTE(LOWER(TRIM(SUBSTITUTE(SUBSTITUTE(SUBSTITUTE(SUBSTITUTE(SUBSTITUTE(SUBSTITUTE(SUBSTITUTE(SUBSTITUTE(SUBSTITUTE(SUBSTITUTE(SUBSTITUTE(D26,".",""),",",""),";",""),":",""),"!",""),"?",""),"""",""),"'",""),"’",""),"“",""),"”","")))," |","|"),"| ","|")) | O26: =IF($A26="","",LOWER(TRIM(SUBSTITUTE(SUBSTITUTE(SUBSTITUTE(SUBSTITUTE(SUBSTITUTE(SUBSTITUTE(SUBSTITUTE(SUBSTITUTE(SUBSTITUTE(SUBSTITUTE(SUBSTITUTE(E26,".",""),",",""),";",""),":",""),"!",""),"?",""),"""",""),"'",""),"’",""),"“",""),"”","")))) | P26: =IF($A26="","",LOWER(TRIM(SUBSTITUTE(SUBSTITUTE(SUBSTITUTE(SUBSTITUTE(SUBSTITUTE(SUBSTITUTE(SUBSTITUTE(SUBSTITUTE(SUBSTITUTE(SUBSTITUTE(SUBSTITUTE(F26,".",""),",",""),";",""),":",""),"!",""),"?",""),"""",""),"'",""),"’",""),"“",""),"”","")))) | Q26: =IF($A26="","",LOWER(TRIM(SUBSTITUTE(SUBSTITUTE(SUBSTITUTE(SUBSTITUTE(SUBSTITUTE(SUBSTITUTE(SUBSTITUTE(SUBSTITUTE(SUBSTITUTE(SUBSTITUTE(SUBSTITUTE(G26,".",""),",",""),";",""),":",""),"!",""),"?",""),"""",""),"'",""),"’",""),"“",""),"”","")))) | R26: =IF($A26="","",LEN(O26)) | S26: =IF($A26="","",IF(O26="",0,LEN(O26)-LEN(SUBSTITUTE(O26," ",""))+1)) | T26: =IF($A26="","",IF(AND(O26<>"",OR(O26=M26,AND(N26<>"",ISNUMBER(FIND("|"&O26&"|","|"&N26&"|"))))),1,0)) | U26: =IF($A26="","",IF(AND(Q26<>"",OR(Q26=M26,AND(N26<>"",ISNUMBER(FIND("|"&Q26&"|","|"&N26&"|"))))),1,0)) | V26: =IF($A26="","",IF(P26=O26,1,0)) | W26: =IF($A26="","",IF(Q26=O26,1,0)) | X26: =IF(OR($A26="",$H26=""),"",IF(AND($H26=1,T26=1),"TA",IF(AND($H26=0,T26=1),"FA",IF($H26=1,"FR","TR")))) | Y26: =IF(OR($A26="",$H26=""),"",IF(AND($H26=1,U26=1),"TA",IF(AND($H26=0,U26=1),"FA",IF($H26=1,"FR","TR"))))
... M254: =IF($A254="","",LOWER(TRIM(SUBSTITUTE(SUBSTITUTE(SUBSTITUTE(SUBSTITUTE(SUBSTITUTE(SUBSTITUTE(SUBSTITUTE(SUBSTITUTE(SUBSTITUTE(SUBSTITUTE(SUBSTITUTE(C254,".",""),",",""),";",""),":",""),"!",""),"?",""),"""",""),"'",""),"’",""),"“",""),"”","")))) | N254: =IF($A254="","",SUBSTITUTE(SUBSTITUTE(LOWER(TRIM(SUBSTITUTE(SUBSTITUTE(SUBSTITUTE(SUBSTITUTE(SUBSTITUTE(SUBSTITUTE(SUBSTITUTE(SUBSTITUTE(SUBSTITUTE(SUBSTITUTE(SUBSTITUTE(D254,".",""),",",""),";",""),":",""),"!",""),"?",""),"""",""),"'",""),"’",""),"“",""),"”","")))," |","|"),"| ","|")) | O254: =IF($A254="","",LOWER(TRIM(SUBSTITUTE(SUBSTITUTE(SUBSTITUTE(SUBSTITUTE(SUBSTITUTE(SUBSTITUTE(SUBSTITUTE(SUBSTITUTE(SUBSTITUTE(SUBSTITUTE(SUBSTITUTE(E254,".",""),",",""),";",""),":",""),"!",""),"?",""),"""",""),"'",""),"’",""),"“",""),"”","")))) | P254: =IF($A254="","",LOWER(TRIM(SUBSTITUTE(SUBSTITUTE(SUBSTITUTE(SUBSTITUTE(SUBSTITUTE(SUBSTITUTE(SUBSTITUTE(SUBSTITUTE(SUBSTITUTE(SUBSTITUTE(SUBSTITUTE(F254,".",""),",",""),";",""),":",""),"!",""),"?",""),"""",""),"'",""),"’",""),"“",""),"”","")))) | Q254: =IF($A254="","",LOWER(TRIM(SUBSTITUTE(SUBSTITUTE(SUBSTITUTE(SUBSTITUTE(SUBSTITUTE(SUBSTITUTE(SUBSTITUTE(SUBSTITUTE(SUBSTITUTE(SUBSTITUTE(SUBSTITUTE(G254,".",""),",",""),";",""),":",""),"!",""),"?",""),"""",""),"'",""),"’",""),"“",""),"”","")))) | R254: =IF($A254="","",LEN(O254)) | S254: =IF($A254="","",IF(O254="",0,LEN(O254)-LEN(SUBSTITUTE(O254," ",""))+1)) | T254: =IF($A254="","",IF(AND(O254<>"",OR(O254=M254,AND(N254<>"",ISNUMBER(FIND("|"&O254&"|","|"&N254&"|"))))),1,0)) | U254: =IF($A254="","",IF(AND(Q254<>"",OR(Q254=M254,AND(N254<>"",ISNUMBER(FIND("|"&Q254&"|","|"&N254&"|"))))),1,0)) | V254: =IF($A254="","",IF(P254=O254,1,0)) | W254: =IF($A254="","",IF(Q254=O254,1,0)) | X254: =IF(OR($A254="",$H254=""),"",IF(AND($H254=1,T254=1),"TA",IF(AND($H254=0,T254=1),"FA",IF($H254=1,"FR","TR")))) | Y254: =IF(OR($A254="",$H254=""),"",IF(AND($H254=1,U254=1),"TA",IF(AND($H254=0,U254=1),"FA",IF($H254=1,"FR","TR"))))
